Watching for file changes with StatReloader
/root/qiuyue/power/power/settings.py changed, reloading.
Performing system checks...

System check identified no issues (0 silenced).

You have 18 unapplied migration(s). Your project may not work properly until you apply the migrations for app(s): admin, auth, contenttypes, sessions.
Run 'python manage.py migrate' to apply them.
April 16, 2023 - 09:06:42
Django version 3.2, using settings 'power.settings'
Starting development server at http://127.0.0.1:8000/
Quit the server with CONTROL-C.
Watching for file changes with StatReloader
/root/qiuyue/power/power/settings.py changed, reloading.
Performing system checks...

System check identified no issues (0 silenced).

You have 18 unapplied migration(s). Your project may not work properly until you apply the migrations for app(s): admin, auth, contenttypes, sessions.
Run 'python manage.py migrate' to apply them.
April 16, 2023 - 09:09:35
Django version 3.2, using settings 'power.settings'
Starting development server at http://127.0.0.1:8000/
Quit the server with CONTROL-C.
Watching for file changes with StatReloader
/root/qiuyue/power/grid/views.py changed, reloading.
Performing system checks...

System check identified no issues (0 silenced).

You have 18 unapplied migration(s). Your project may not work properly until you apply the migrations for app(s): admin, auth, contenttypes, sessions.
Run 'python manage.py migrate' to apply them.
April 16, 2023 - 09:09:55
Django version 3.2, using settings 'power.settings'
Starting development server at http://127.0.0.1:8000/
Quit the server with CONTROL-C.
Watching for file changes with StatReloader
Exception in thread django-main-thread:
Traceback (most recent call last):
  File "/root/anaconda3/envs/grid_system/lib/python3.6/threading.py", line 916, in _bootstrap_inner
    self.run()
  File "/root/anaconda3/envs/grid_system/lib/python3.6/threading.py", line 864, in run
    self._target(*self._args, **self._kwargs)
  File "/root/anaconda3/envs/grid_system/lib/python3.6/site-packages/django/utils/autoreload.py", line 64, in wrapper
    fn(*args, **kwargs)
  File "/root/anaconda3/envs/grid_system/lib/python3.6/site-packages/django/core/management/commands/runserver.py", line 118, in inner_run
    self.check(display_num_errors=True)
  File "/root/anaconda3/envs/grid_system/lib/python3.6/site-packages/django/core/management/base.py", line 423, in check
    databases=databases,
  File "/root/anaconda3/envs/grid_system/lib/python3.6/site-packages/django/core/checks/registry.py", line 76, in run_checks
    new_errors = check(app_configs=app_configs, databases=databases)
  File "/root/anaconda3/envs/grid_system/lib/python3.6/site-packages/django/core/checks/urls.py", line 40, in check_url_namespaces_unique
    all_namespaces = _load_all_namespaces(resolver)
  File "/root/anaconda3/envs/grid_system/lib/python3.6/site-packages/django/core/checks/urls.py", line 57, in _load_all_namespaces
    url_patterns = getattr(resolver, 'url_patterns', [])
  File "/root/anaconda3/envs/grid_system/lib/python3.6/site-packages/django/utils/functional.py", line 48, in __get__
    res = instance.__dict__[self.name] = self.func(instance)
  File "/root/anaconda3/envs/grid_system/lib/python3.6/site-packages/django/urls/resolvers.py", line 598, in url_patterns
    patterns = getattr(self.urlconf_module, "urlpatterns", self.urlconf_module)
  File "/root/anaconda3/envs/grid_system/lib/python3.6/site-packages/django/utils/functional.py", line 48, in __get__
    res = instance.__dict__[self.name] = self.func(instance)
  File "/root/anaconda3/envs/grid_system/lib/python3.6/site-packages/django/urls/resolvers.py", line 591, in urlconf_module
    return import_module(self.urlconf_name)
  File "/root/anaconda3/envs/grid_system/lib/python3.6/importlib/__init__.py", line 126, in import_module
    return _bootstrap._gcd_import(name[level:], package, level)
  File "<frozen importlib._bootstrap>", line 994, in _gcd_import
  File "<frozen importlib._bootstrap>", line 971, in _find_and_load
  File "<frozen importlib._bootstrap>", line 955, in _find_and_load_unlocked
  File "<frozen importlib._bootstrap>", line 665, in _load_unlocked
  File "<frozen importlib._bootstrap_external>", line 678, in exec_module
  File "<frozen importlib._bootstrap>", line 219, in _call_with_frames_removed
  File "/root/qiuyue/power/power/urls.py", line 21, in <module>
    path('grid/', include('grid.urls')),
  File "/root/anaconda3/envs/grid_system/lib/python3.6/site-packages/django/urls/conf.py", line 34, in include
    urlconf_module = import_module(urlconf_module)
  File "/root/anaconda3/envs/grid_system/lib/python3.6/importlib/__init__.py", line 126, in import_module
    return _bootstrap._gcd_import(name[level:], package, level)
  File "<frozen importlib._bootstrap>", line 994, in _gcd_import
  File "<frozen importlib._bootstrap>", line 971, in _find_and_load
  File "<frozen importlib._bootstrap>", line 955, in _find_and_load_unlocked
  File "<frozen importlib._bootstrap>", line 665, in _load_unlocked
  File "<frozen importlib._bootstrap_external>", line 678, in exec_module
  File "<frozen importlib._bootstrap>", line 219, in _call_with_frames_removed
  File "/root/qiuyue/power/grid/urls.py", line 3, in <module>
    from grid import views
  File "/root/qiuyue/power/grid/views.py", line 134, in <module>
    @cors_origin_allow_all
NameError: name 'cors_origin_allow_all' is not defined

/root/qiuyue/power/grid/views.py changed, reloading.
Performing system checks...

Watching for file changes with StatReloader
